TAP version 13
---tty-stream-chunk-separator
# TypeError: test.serial.test is not a function
not ok 1 - TypeError: test.serial.test is not a function
  ---
    name: TypeError
    message: test.serial.test is not a function
    at: 'Object.<anonymous> (test-tap/fixture/report/regular/bad-test-chain.js:3:13)'
  ...
---tty-stream-chunk-separator
# bad-test-chain.js exited with a non-zero exit code: 1
not ok 2 - bad-test-chain.js exited with a non-zero exit code: 1
---tty-stream-chunk-separator
# nested-objects â€º format with max depth 4
not ok 3 - nested-objects [90m[2mâ€º[22m[39m format with max depth 4
  ---
    name: AssertionError
    assertion: deepEqual
    values:
      'Difference:': |2-
          {
            a: {
              b: {
                foo: 'bar',
              },
            },
        +   c: {
        +     d: {
        +       e: {
        +         foo: 'bar',
        +       },
        +     },
        +   },
          }
    at: 'test-tap/fixture/report/regular/nested-objects.js:28:4'
  ...
---tty-stream-chunk-separator
# nested-objects â€º format like with max depth 4
not ok 4 - nested-objects [90m[2mâ€º[22m[39m format like with max depth 4
  ---
    name: AssertionError
    assertion: like
    values:
      'Difference:': |2-
          {
            a: {
              b: {
        -       foo: 'bar',
        +       foo: 'qux',
              },
            },
          }
    at: 'test-tap/fixture/report/regular/nested-objects.js:54:4'
  ...
---tty-stream-chunk-separator
# output-in-hook â€º before hook
---tty-stream-chunk-separator
# output-in-hook â€º before hook
---tty-stream-chunk-separator
  # before
---tty-stream-chunk-separator
# output-in-hook â€º beforeEach hook for passing test
---tty-stream-chunk-separator
  # beforeEach
---tty-stream-chunk-separator
# output-in-hook â€º beforeEach hook for failing test
---tty-stream-chunk-separator
  # beforeEach
---tty-stream-chunk-separator
# output-in-hook â€º passing test
ok 5 - output-in-hook [90m[2mâ€º[22m[39m passing test
---tty-stream-chunk-separator
# output-in-hook â€º failing test
not ok 6 - output-in-hook [90m[2mâ€º[22m[39m failing test
  ---
    name: AssertionError
    message: Test failed via `t.fail()`
    assertion: fail
    at: 'test-tap/fixture/report/regular/output-in-hook.js:34:4'
  ...
---tty-stream-chunk-separator
# output-in-hook â€º afterEach hook for passing test
---tty-stream-chunk-separator
  # afterEach
---tty-stream-chunk-separator
# output-in-hook â€º afterEach.always hook for failing test
---tty-stream-chunk-separator
  # afterEachAlways
---tty-stream-chunk-separator
# output-in-hook â€º afterEach.always hook for passing test
---tty-stream-chunk-separator
  # afterEachAlways
---tty-stream-chunk-separator
# output-in-hook â€º cleanup
---tty-stream-chunk-separator
  # afterAlways
---tty-stream-chunk-separator
# test â€º skip
ok 7 - test [90m[2mâ€º[22m[39m skip # SKIP
---tty-stream-chunk-separator
# test â€º todo
not ok 8 - test [90m[2mâ€º[22m[39m todo # TODO
---tty-stream-chunk-separator
# test â€º passes
ok 9 - test [90m[2mâ€º[22m[39m passes
---tty-stream-chunk-separator
# test â€º fails
not ok 10 - test [90m[2mâ€º[22m[39m fails
  ---
    name: AssertionError
    message: Test failed via `t.fail()`
    assertion: fail
    at: 'test-tap/fixture/report/regular/test.js:9:22'
  ...
---tty-stream-chunk-separator
# test â€º known failure
ok 11 - test [90m[2mâ€º[22m[39m known failure
---tty-stream-chunk-separator
# test â€º no longer failing
not ok 12 - test [90m[2mâ€º[22m[39m no longer failing
  ---
    name: Error
    message: >-
      Test was expected to fail, but succeeded, you should stop marking the test as
      failing
    at: ''
  ...
---tty-stream-chunk-separator
# test â€º logs
not ok 13 - test [90m[2mâ€º[22m[39m logs
  * hello
  * world
  ---
    name: AssertionError
    message: Test failed via `t.fail()`
    assertion: fail
    at: 'test-tap/fixture/report/regular/test.js:18:4'
  ...
---tty-stream-chunk-separator
# test â€º formatted
not ok 14 - test [90m[2mâ€º[22m[39m formatted
  ---
    name: AssertionError
    assertion: deepEqual
    values:
      'Difference:': |-
        - 'foo'
        + 'bar'
    at: 'test-tap/fixture/report/regular/test.js:22:4'
  ...
---tty-stream-chunk-separator
# test â€º power-assert
not ok 15 - test [90m[2mâ€º[22m[39m power-assert
  ---
    name: AssertionError
    assertion: assert
    operator: '!!'
    values:
      'Value is not truthy:': ''''''
    at: 'test-tap/fixture/report/regular/test.js:27:4'
  ...
---tty-stream-chunk-separator
# test â€º bad throws
not ok 16 - test [90m[2mâ€º[22m[39m bad throws
  ---
    name: AssertionError
    message: Improper usage of `t.throws()` detected
    assertion: throws
    values:
      'The following error was thrown, possibly before `t.throws()` could be called:': |-
        Error {
          message: 'err',
        }
    at: |-
      fn (test-tap/fixture/report/regular/test.js:32:9)
      test-tap/fixture/report/regular/test.js:35:11
  ...
---tty-stream-chunk-separator
# test â€º bad notThrows
not ok 17 - test [90m[2mâ€º[22m[39m bad notThrows
  ---
    name: AssertionError
    message: Improper usage of `t.notThrows()` detected
    assertion: notThrows
    values:
      'The following error was thrown, possibly before `t.notThrows()` could be called:': |-
        Error {
          message: 'err',
        }
    at: |-
      fn (test-tap/fixture/report/regular/test.js:40:9)
      test-tap/fixture/report/regular/test.js:43:14
  ...
---tty-stream-chunk-separator
# test â€º implementation throws non-error
not ok 18 - test [90m[2mâ€º[22m[39m implementation throws non-error
  ---
    name: AssertionError
    message: Error thrown in test
    values:
      'Error thrown in test:': 'null'
    at: ''
  ...
---tty-stream-chunk-separator
# traces-in-t-throws â€º throws
not ok 19 - traces-in-t-throws [90m[2mâ€º[22m[39m throws
  ---
    name: AssertionError
    assertion: throws
    values:
      'Function threw unexpected exception:': |-
        Error {
          message: 'uh-oh',
        }
      'Expected instance of:': 'Function TypeError {}'
    at: |-
      throwError (test-tap/fixture/report/regular/traces-in-t-throws.js:4:8)
      test-tap/fixture/report/regular/traces-in-t-throws.js:12:17
      test-tap/fixture/report/regular/traces-in-t-throws.js:12:4
  ...
---tty-stream-chunk-separator
# traces-in-t-throws â€º notThrows
not ok 20 - traces-in-t-throws [90m[2mâ€º[22m[39m notThrows
  ---
    name: AssertionError
    assertion: notThrows
    values:
      'Function threw:': |-
        Error {
          message: 'uh-oh',
        }
    at: |-
      throwError (test-tap/fixture/report/regular/traces-in-t-throws.js:4:8)
      test-tap/fixture/report/regular/traces-in-t-throws.js:16:20
      test-tap/fixture/report/regular/traces-in-t-throws.js:16:4
  ...
---tty-stream-chunk-separator
# traces-in-t-throws â€º notThrowsAsync
not ok 21 - traces-in-t-throws [90m[2mâ€º[22m[39m notThrowsAsync
  ---
    name: AssertionError
    assertion: notThrowsAsync
    values:
      'Function threw:': |-
        Error {
          message: 'uh-oh',
        }
    at: |-
      throwError (test-tap/fixture/report/regular/traces-in-t-throws.js:4:8)
      test-tap/fixture/report/regular/traces-in-t-throws.js:20:25
      test-tap/fixture/report/regular/traces-in-t-throws.js:20:4
  ...
---tty-stream-chunk-separator
# traces-in-t-throws â€º throwsAsync
not ok 22 - traces-in-t-throws [90m[2mâ€º[22m[39m throwsAsync
  ---
    name: AssertionError
    assertion: throwsAsync
    values:
      'Function threw synchronously. Use `t.throws()` instead:': |-
        Error {
          message: 'uh-oh',
        }
    at: >-
      throwError (test-tap/fixture/report/regular/traces-in-t-throws.js:4:8)

      t.throwsAsync.instanceOf
      (test-tap/fixture/report/regular/traces-in-t-throws.js:24:22)

      test-tap/fixture/report/regular/traces-in-t-throws.js:24:4
  ...
---tty-stream-chunk-separator
# traces-in-t-throws â€º throwsAsync different error
not ok 23 - traces-in-t-throws [90m[2mâ€º[22m[39m throwsAsync different error
  ---
    name: AssertionError
    assertion: throwsAsync
    values:
      'Returned promise rejected with unexpected exception:': |-
        Error {
          message: 'uh-oh',
        }
      'Expected instance of:': 'Function TypeError {}'
    at: >-
      returnRejectedPromise
      (test-tap/fixture/report/regular/traces-in-t-throws.js:8:24)

      test-tap/fixture/report/regular/traces-in-t-throws.js:28:11
  ...
---tty-stream-chunk-separator
# uncaught-exception â€º passes
ok 24 - uncaught-exception [90m[2mâ€º[22m[39m passes
---tty-stream-chunk-separator
# Error: Canâ€™t catch me
not ok 25 - Error: Canâ€™t catch me
  ---
    name: Error
    message: Canâ€™t catch me
    at: >-
      Immediate.<anonymous>
      (test-tap/fixture/report/regular/uncaught-exception.js:5:9)

      processImmediate (internal/timers.js)
  ...
---tty-stream-chunk-separator
# uncaught-exception.js exited with a non-zero exit code: 1
not ok 26 - uncaught-exception.js exited with a non-zero exit code: 1
---tty-stream-chunk-separator
# unhandled-rejection â€º passes
ok 27 - unhandled-rejection [90m[2mâ€º[22m[39m passes
---tty-stream-chunk-separator
# unhandled-rejection â€º unhandled non-error rejection
ok 28 - unhandled-rejection [90m[2mâ€º[22m[39m unhandled non-error rejection
---tty-stream-chunk-separator
# Error: Canâ€™t catch me
not ok 29 - Error: Canâ€™t catch me
  ---
    name: Error
    message: Canâ€™t catch me
    at: 'passes (test-tap/fixture/report/regular/unhandled-rejection.js:4:17)'
  ...
---tty-stream-chunk-separator
# unhandled-rejection
not ok 30 - unhandled-rejection
  ---
    message: Non-error object
    formatted: 'null'
  ...
---tty-stream-chunk-separator

1..24
# tests 23
# pass 6
# skip 1
# fail 23

---tty-stream-chunk-separator
