TAP version 13
---tty-stream-chunk-separator
# TypeError: test.serial.test is not a function
not ok 1 - TypeError: test.serial.test is not a function
  ---
    name: TypeError
    message: test.serial.test is not a function
    at: 'Object.<anonymous> (test-tap/fixture/report/regular/bad-test-chain.js:3:13)'
  ...
---tty-stream-chunk-separator
# bad-test-chain.js exited with a non-zero exit code: 1
not ok 2 - bad-test-chain.js exited with a non-zero exit code: 1
---tty-stream-chunk-separator
# output-in-hook â€º before hook
---tty-stream-chunk-separator
# output-in-hook â€º before hook
---tty-stream-chunk-separator
  # before
---tty-stream-chunk-separator
# output-in-hook â€º beforeEach hook for passing test
---tty-stream-chunk-separator
  # beforeEach
---tty-stream-chunk-separator
# output-in-hook â€º beforeEach hook for failing test
---tty-stream-chunk-separator
  # beforeEach
---tty-stream-chunk-separator
# output-in-hook â€º passing test
ok 3 - output-in-hook [90m[2mâ€º[22m[39m passing test
---tty-stream-chunk-separator
# output-in-hook â€º failing test
not ok 4 - output-in-hook [90m[2mâ€º[22m[39m failing test
  ---
    name: AssertionError
    message: Test failed via `t.fail()`
    assertion: fail
    at: |-
      t (test-tap/fixture/report/regular/output-in-hook.js:34:4)
      process._tickCallback (internal/process/next_tick.js:68:7)
  ...
---tty-stream-chunk-separator
# output-in-hook â€º afterEach hook for passing test
---tty-stream-chunk-separator
  # afterEach
---tty-stream-chunk-separator
# output-in-hook â€º afterEach.always hook for failing test
---tty-stream-chunk-separator
  # afterEachAlways
---tty-stream-chunk-separator
# output-in-hook â€º afterEach.always hook for passing test
---tty-stream-chunk-separator
  # afterEachAlways
---tty-stream-chunk-separator
# output-in-hook â€º cleanup
---tty-stream-chunk-separator
  # afterAlways
---tty-stream-chunk-separator
# slow â€º slow
ok 5 - slow [90m[2mâ€º[22m[39m slow
---tty-stream-chunk-separator
# test â€º skip
ok 6 - test [90m[2mâ€º[22m[39m skip # SKIP
---tty-stream-chunk-separator
# test â€º todo
not ok 7 - test [90m[2mâ€º[22m[39m todo # TODO
---tty-stream-chunk-separator
# test â€º passes
ok 8 - test [90m[2mâ€º[22m[39m passes
---tty-stream-chunk-separator
# test â€º fails
not ok 9 - test [90m[2mâ€º[22m[39m fails
  ---
    name: AssertionError
    message: Test failed via `t.fail()`
    assertion: fail
    at: |-
      t (test-tap/fixture/report/regular/test.js:9:22)
      process._tickCallback (internal/process/next_tick.js:68:7)
  ...
---tty-stream-chunk-separator
# test â€º known failure
ok 10 - test [90m[2mâ€º[22m[39m known failure
---tty-stream-chunk-separator
# test â€º no longer failing
not ok 11 - test [90m[2mâ€º[22m[39m no longer failing
  ---
    name: Error
    message: >-
      Test was expected to fail, but succeeded, you should stop marking the test as
      failing
    at: 'process._tickCallback (internal/process/next_tick.js:68:7)'
  ...
---tty-stream-chunk-separator
# test â€º logs
not ok 12 - test [90m[2mâ€º[22m[39m logs
  * hello
  * world
  ---
    name: AssertionError
    message: Test failed via `t.fail()`
    assertion: fail
    at: |-
      t (test-tap/fixture/report/regular/test.js:18:4)
      process._tickCallback (internal/process/next_tick.js:68:7)
  ...
---tty-stream-chunk-separator
# test â€º formatted
not ok 13 - test [90m[2mâ€º[22m[39m formatted
  ---
    name: AssertionError
    assertion: deepEqual
    values:
      'Difference:': |-
        - 'foo'
        + 'bar'
    at: |-
      t (test-tap/fixture/report/regular/test.js:22:4)
      process._tickCallback (internal/process/next_tick.js:68:7)
  ...
---tty-stream-chunk-separator
# test â€º power-assert
not ok 14 - test [90m[2mâ€º[22m[39m power-assert
  ---
    name: AssertionError
    assertion: assert
    operator: '!!'
    values:
      'Value is not truthy:': ''''''
    at: |-
      t (test-tap/fixture/report/regular/test.js:27:4)
      process._tickCallback (internal/process/next_tick.js:68:7)
  ...
---tty-stream-chunk-separator
# test â€º bad throws
not ok 15 - test [90m[2mâ€º[22m[39m bad throws
  ---
    name: AssertionError
    message: Improper usage of `t.throws()` detected
    assertion: throws
    values:
      'The following error was thrown, possibly before `t.throws()` could be called:': |-
        Error {
          message: 'err',
        }
    at: |-
      fn (test-tap/fixture/report/regular/test.js:32:9)
      t (test-tap/fixture/report/regular/test.js:35:11)
      process._tickCallback (internal/process/next_tick.js:68:7)
  ...
---tty-stream-chunk-separator
# test â€º bad notThrows
not ok 16 - test [90m[2mâ€º[22m[39m bad notThrows
  ---
    name: AssertionError
    message: Improper usage of `t.notThrows()` detected
    assertion: notThrows
    values:
      'The following error was thrown, possibly before `t.notThrows()` could be called:': |-
        Error {
          message: 'err',
        }
    at: |-
      fn (test-tap/fixture/report/regular/test.js:40:9)
      t (test-tap/fixture/report/regular/test.js:43:14)
      process._tickCallback (internal/process/next_tick.js:68:7)
  ...
---tty-stream-chunk-separator
# test â€º implementation throws non-error
not ok 17 - test [90m[2mâ€º[22m[39m implementation throws non-error
  ---
    name: AssertionError
    message: Error thrown in test
    values:
      'Error thrown in test:': 'null'
    at: 'process._tickCallback (internal/process/next_tick.js:68:7)'
  ...
---tty-stream-chunk-separator
# traces-in-t-throws â€º throws
not ok 18 - traces-in-t-throws [90m[2mâ€º[22m[39m throws
  ---
    name: AssertionError
    assertion: throws
    values:
      'Function threw unexpected exception:': |-
        Error {
          message: 'uh-oh',
        }
      'Expected instance of:': 'Function TypeError {}'
    at: |-
      throwError (test-tap/fixture/report/regular/traces-in-t-throws.js:4:8)
      t.throws (test-tap/fixture/report/regular/traces-in-t-throws.js:12:17)
      t (test-tap/fixture/report/regular/traces-in-t-throws.js:12:4)
      process._tickCallback (internal/process/next_tick.js:68:7)
  ...
---tty-stream-chunk-separator
# traces-in-t-throws â€º notThrows
not ok 19 - traces-in-t-throws [90m[2mâ€º[22m[39m notThrows
  ---
    name: AssertionError
    assertion: notThrows
    values:
      'Function threw:': |-
        Error {
          message: 'uh-oh',
        }
    at: |-
      throwError (test-tap/fixture/report/regular/traces-in-t-throws.js:4:8)
      t.notThrows (test-tap/fixture/report/regular/traces-in-t-throws.js:16:20)
      t (test-tap/fixture/report/regular/traces-in-t-throws.js:16:4)
      process._tickCallback (internal/process/next_tick.js:68:7)
  ...
---tty-stream-chunk-separator
# traces-in-t-throws â€º notThrowsAsync
not ok 20 - traces-in-t-throws [90m[2mâ€º[22m[39m notThrowsAsync
  ---
    name: AssertionError
    assertion: notThrowsAsync
    values:
      'Function threw:': |-
        Error {
          message: 'uh-oh',
        }
    at: |-
      throwError (test-tap/fixture/report/regular/traces-in-t-throws.js:4:8)
      t.notThrowsAsync (test-tap/fixture/report/regular/traces-in-t-throws.js:20:25)
      t (test-tap/fixture/report/regular/traces-in-t-throws.js:20:4)
      process._tickCallback (internal/process/next_tick.js:68:7)
  ...
---tty-stream-chunk-separator
# traces-in-t-throws â€º throwsAsync
not ok 21 - traces-in-t-throws [90m[2mâ€º[22m[39m throwsAsync
  ---
    name: AssertionError
    assertion: throwsAsync
    values:
      'Function threw synchronously. Use `t.throws()` instead:': |-
        Error {
          message: 'uh-oh',
        }
    at: |-
      throwError (test-tap/fixture/report/regular/traces-in-t-throws.js:4:8)
      t.throwsAsync (test-tap/fixture/report/regular/traces-in-t-throws.js:24:22)
      t (test-tap/fixture/report/regular/traces-in-t-throws.js:24:4)
      process._tickCallback (internal/process/next_tick.js:68:7)
  ...
---tty-stream-chunk-separator
# traces-in-t-throws â€º throwsAsync different error
not ok 22 - traces-in-t-throws [90m[2mâ€º[22m[39m throwsAsync different error
  ---
    name: AssertionError
    assertion: throwsAsync
    values:
      'Returned promise rejected with unexpected exception:': |-
        Error {
          message: 'uh-oh',
        }
      'Expected instance of:': 'Function TypeError {}'
    at: >-
      returnRejectedPromise
      (test-tap/fixture/report/regular/traces-in-t-throws.js:8:24)

      t (test-tap/fixture/report/regular/traces-in-t-throws.js:28:11)

      process._tickCallback (internal/process/next_tick.js:68:7)
  ...
---tty-stream-chunk-separator
# uncaught-exception â€º passes
ok 23 - uncaught-exception [90m[2mâ€º[22m[39m passes
---tty-stream-chunk-separator
# Error: Canâ€™t catch me
not ok 24 - Error: Canâ€™t catch me
  ---
    name: Error
    message: Canâ€™t catch me
    at: 'Timeout.setTimeout (test-tap/fixture/report/regular/uncaught-exception.js:5:9)'
  ...
---tty-stream-chunk-separator
# uncaught-exception.js exited with a non-zero exit code: 1
not ok 25 - uncaught-exception.js exited with a non-zero exit code: 1
---tty-stream-chunk-separator
# unhandled-rejection â€º passes
ok 26 - unhandled-rejection [90m[2mâ€º[22m[39m passes
---tty-stream-chunk-separator
# unhandled-rejection â€º unhandled non-error rejection
ok 27 - unhandled-rejection [90m[2mâ€º[22m[39m unhandled non-error rejection
---tty-stream-chunk-separator
# Error: Canâ€™t catch me
not ok 28 - Error: Canâ€™t catch me
  ---
    name: Error
    message: Canâ€™t catch me
    at: |-
      passes (test-tap/fixture/report/regular/unhandled-rejection.js:4:17)
      process._tickCallback (internal/process/next_tick.js:68:7)
  ...
---tty-stream-chunk-separator
# unhandled-rejection
not ok 29 - unhandled-rejection
  ---
    message: Non-error object
    formatted: 'null'
  ...
---tty-stream-chunk-separator

1..23
# tests 22
# pass 7
# skip 1
# fail 21

---tty-stream-chunk-separator
