TAP version 13
---tty-stream-chunk-separator
not ok 1 - TypeError: test.serial.test is not a function
  ---
    name: TypeError
    message: test.serial.test is not a function
    at: 'Object.<anonymous> (~/test-tap/fixture/report/regular/bad-test-chain.cjs:3:13)'
  ...
---tty-stream-chunk-separator
not ok 2 - bad-test-chain.cjs exited with a non-zero exit code: 1
---tty-stream-chunk-separator
not ok 3 - nested-objects › format with max depth 4
  ---
    name: AssertionError
    assertion: t.deepEqual()
    details:
      'Difference (- actual, + expected):': |2-
          {
            a: {
              b: {
                foo: 'bar',
              },
            },
        +   c: {
        +     d: {
        +       e: {
        +         foo: 'bar',
        +       },
        +     },
        +   },
          }
    message: ''
    at: 'ExecutionContext.deepEqual (/lib/assert.js:339:15)'
  ...
---tty-stream-chunk-separator
not ok 4 - nested-objects › format like with max depth 4
  ---
    name: AssertionError
    assertion: t.like()
    details:
      'Difference (- actual, + expected):': |2-
          {
            a: {
              b: {
        -       foo: 'bar',
        +       foo: 'qux',
              },
            },
          }
    message: ''
    at: 'ExecutionContext.like (/lib/assert.js:391:15)'
  ...
---tty-stream-chunk-separator
# output-in-hook › before hook
---tty-stream-chunk-separator
# output-in-hook › before hook
---tty-stream-chunk-separator
#   before
---tty-stream-chunk-separator
# output-in-hook › beforeEach hook for passing test
---tty-stream-chunk-separator
#   beforeEach
---tty-stream-chunk-separator
# output-in-hook › beforeEach hook for failing test
---tty-stream-chunk-separator
#   beforeEach
---tty-stream-chunk-separator
ok 5 - output-in-hook › passing test
---tty-stream-chunk-separator
not ok 6 - output-in-hook › failing test
  ---
    name: AssertionError
    assertion: t.fail()
    message: Test failed via `t.fail()`
    at: 'ExecutionContext.fail (/lib/assert.js:287:15)'
  ...
---tty-stream-chunk-separator
# output-in-hook › afterEach hook for passing test
---tty-stream-chunk-separator
#   afterEach
---tty-stream-chunk-separator
# output-in-hook › afterEach.always hook for failing test
---tty-stream-chunk-separator
#   afterEachAlways
---tty-stream-chunk-separator
# output-in-hook › afterEach.always hook for passing test
---tty-stream-chunk-separator
#   afterEachAlways
---tty-stream-chunk-separator
# output-in-hook › cleanup
---tty-stream-chunk-separator
#   afterAlways
---tty-stream-chunk-separator
ok 7 - test › skip # SKIP
---tty-stream-chunk-separator
not ok 8 - test › todo # TODO
---tty-stream-chunk-separator
ok 9 - test › passes
---tty-stream-chunk-separator
not ok 10 - test › fails
  ---
    name: AssertionError
    assertion: t.fail()
    message: Test failed via `t.fail()`
    at: 'ExecutionContext.fail (/lib/assert.js:287:15)'
  ...
---tty-stream-chunk-separator
ok 11 - test › known failure
---tty-stream-chunk-separator
not ok 12 - test › no longer failing
  ---
    name: AssertionError
    message: >-
      Test was expected to fail, but succeeded, you should stop marking the test as
      failing
    at: 'Test.finish (/lib/test.js:633:28)'
  ...
---tty-stream-chunk-separator
not ok 13 - test › logs
#   hello
#   world
  ---
    name: AssertionError
    assertion: t.fail()
    message: Test failed via `t.fail()`
    at: 'ExecutionContext.fail (/lib/assert.js:287:15)'
  ...
---tty-stream-chunk-separator
not ok 14 - test › formatted
  ---
    name: AssertionError
    assertion: t.deepEqual()
    details:
      'Difference (- actual, + expected):': |-
        - 'foo'
        + 'bar'
    message: ''
    at: 'ExecutionContext.deepEqual (/lib/assert.js:339:15)'
  ...
---tty-stream-chunk-separator
not ok 15 - test › implementation throws non-error
  ---
    name: AssertionError
    details:
      'Error thrown in test:': 'null'
    message: Error thrown in test
    at: 'Test.run (/lib/test.js:546:25)'
  ...
---tty-stream-chunk-separator
not ok 16 - traces-in-t-throws › throws
  ---
    name: AssertionError
    assertion: t.throws()
    details:
      'Function threw unexpected exception:': |-
        Error {
          message: 'uh-oh',
        }
      'Expected instance of:': 'Function TypeError {}'
    message: ''
    at: 'throwError (~/test-tap/fixture/report/regular/traces-in-t-throws.cjs:4:8)'
  ...
---tty-stream-chunk-separator
not ok 17 - traces-in-t-throws › notThrows
  ---
    name: AssertionError
    assertion: t.notThrows()
    details:
      'Function threw:': |-
        Error {
          message: 'uh-oh',
        }
    message: ''
    at: 'throwError (~/test-tap/fixture/report/regular/traces-in-t-throws.cjs:4:8)'
  ...
---tty-stream-chunk-separator
not ok 18 - traces-in-t-throws › notThrowsAsync
  ---
    name: AssertionError
    assertion: t.notThrowsAsync()
    details:
      'Function threw:': |-
        Error {
          message: 'uh-oh',
        }
    message: ''
    at: 'throwError (~/test-tap/fixture/report/regular/traces-in-t-throws.cjs:4:8)'
  ...
---tty-stream-chunk-separator
not ok 19 - traces-in-t-throws › throwsAsync
  ---
    name: AssertionError
    assertion: t.throwsAsync()
    details:
      'Function threw synchronously. Use `t.throws()` instead:': |-
        Error {
          message: 'uh-oh',
        }
    message: ''
    at: 'throwError (~/test-tap/fixture/report/regular/traces-in-t-throws.cjs:4:8)'
  ...
---tty-stream-chunk-separator
not ok 20 - traces-in-t-throws › throwsAsync different error
  ---
    name: AssertionError
    assertion: t.throwsAsync()
    details:
      'Returned promise rejected with unexpected exception:': |-
        Error {
          message: 'uh-oh',
        }
      'Expected instance of:': 'Function TypeError {}'
    message: ''
    at: >-
      returnRejectedPromise
      (~/test-tap/fixture/report/regular/traces-in-t-throws.cjs:8:24)
  ...
---tty-stream-chunk-separator
ok 21 - uncaught-exception › passes
---tty-stream-chunk-separator
not ok 22 - Error: Can’t catch me
  ---
    name: Error
    message: Can’t catch me
    at: >-
      Immediate.<anonymous>
      (~/test-tap/fixture/report/regular/uncaught-exception.cjs:5:9)
  ...
---tty-stream-chunk-separator
not ok 23 - uncaught-exception.cjs exited with a non-zero exit code: 1
---tty-stream-chunk-separator
ok 24 - unhandled-rejection › passes
---tty-stream-chunk-separator
ok 25 - unhandled-rejection › unhandled non-error rejection
---tty-stream-chunk-separator
not ok 26 - Error: Can’t catch me
  ---
    name: Error
    message: Can’t catch me
    at: 'passes (~/test-tap/fixture/report/regular/unhandled-rejection.cjs:4:17)'
  ...
---tty-stream-chunk-separator
not ok 27 - unhandled-rejection
  ---
    message: Non-native error
    formatted: 'null'
  ...
---tty-stream-chunk-separator
not ok 28 - unhandled-rejection.cjs exited with a non-zero exit code: 1
---tty-stream-chunk-separator

1..21
# tests 20
# pass 6
# skip 1
# fail 21

---tty-stream-chunk-separator
